<?xml version="1.0"?>
<robot name="simple_car">
  <!-- Define materials for visualization -->
  <material name="blue">
    <color rgba="0 0 0.8 1"/>
  </material>
  <material name="black">
    <color rgba="0 0 0 1"/>
  </material>

  <!-- Base link (required for proper TF tree) -->
  <link name="base_link"/>

  <!-- Chassis -->
  <link name="chassis">
    <visual>
      <geometry>
        <box size="0.5 0.3 0.2"/>
      </geometry>
      <material name="blue"/>
    </visual>
    <collision>
      <geometry>
        <box size="0.5 0.3 0.2"/>
      </geometry>
    </collision>
    <inertial>
      <mass value="5.0"/>
      <inertia ixx="0.072" ixy="0.0" ixz="0.0" iyy="0.108" iyz="0.0" izz="0.162"/>
    </inertial>
  </link>

  <!-- Connect base_link to chassis -->
  <joint name="base_to_chassis" type="fixed">
    <parent link="base_link"/>
    <child link="chassis"/>
    <origin xyz="0 0 0.1" rpy="0 0 0"/>
  </joint>

  <!-- Right Front Wheel -->
  <link name="right_front_wheel">
    <visual>
      <geometry>
        <cylinder radius="0.1" length="0.05"/>
      </geometry>
      <material name="black"/>
    </visual>
    <collision>
      <geometry>
        <cylinder radius="0.1" length="0.05"/>
      </geometry>
    </collision>
    <inertial>
      <mass value="0.5"/>
      <inertia ixx="0.00125" ixy="0.0" ixz="0.0" iyy="0.00125" iyz="0.0" izz="0.0025"/>
    </inertial>
  </link>

  <!-- Left Front Wheel -->
  <link name="left_front_wheel">
    <visual>
      <geometry>
        <cylinder radius="0.1" length="0.05"/>
      </geometry>
      <material name="black"/>
    </visual>
    <collision>
      <geometry>
        <cylinder radius="0.1" length="0.05"/>
      </geometry>
    </collision>
    <inertial>
      <mass value="0.5"/>
      <inertia ixx="0.00125" ixy="0.0" ixz="0.0" iyy="0.00125" iyz="0.0" izz="0.0025"/>
    </inertial>
  </link>

  <!-- Right Rear Wheel -->
  <link name="right_rear_wheel">
    <visual>
      <geometry>
        <cylinder radius="0.1" length="0.05"/>
      </geometry>
      <material name="black"/>
    </visual>
    <collision>
      <geometry>
        <cylinder radius="0.1" length="0.05"/>
      </geometry>
    </collision>
    <inertial>
      <mass value="0.5"/>
      <inertia ixx="0.00125" ixy="0.0" ixz="0.0" iyy="0.00125" iyz="0.0" izz="0.0025"/>
    </inertial>
  </link>

  <!-- Left Rear Wheel -->
  <link name="left_rear_wheel">
    <visual>
      <geometry>
        <cylinder radius="0.1" length="0.05"/>
      </geometry>
      <material name="black"/>
    </visual>
    <collision>
      <geometry>
        <cylinder radius="0.1" length="0.05"/>
      </geometry>
    </collision>
    <inertial>
      <mass value="0.5"/>
      <inertia ixx="0.00125" ixy="0.0" ixz="0.0" iyy="0.00125" iyz="0.0" izz="0.0025"/>
    </inertial>
  </link>

  <!-- Joints to connect wheels to chassis -->
  <!-- Fixed the rotation axis - should be Y axis for wheel rotation -->
  <joint name="right_front_joint" type="continuous">
    <parent link="chassis"/>
    <child link="right_front_wheel"/>
    <origin xyz="0.15 -0.175 -0.1" rpy="1.5708 0 0"/>
    <axis xyz="0 0 1"/>
  </joint>

  <joint name="left_front_joint" type="continuous">
    <parent link="chassis"/>
    <child link="left_front_wheel"/>
    <origin xyz="0.15 0.175 -0.1" rpy="1.5708 0 0"/>
    <axis xyz="0 0 1"/>
  </joint>

  <joint name="right_rear_joint" type="continuous">
    <parent link="chassis"/>
    <child link="right_rear_wheel"/>
    <origin xyz="-0.15 -0.175 -0.1" rpy="1.5708 0 0"/>
    <axis xyz="0 0 1"/>
  </joint>

  <joint name="left_rear_joint" type="continuous">
    <parent link="chassis"/>
    <child link="left_rear_wheel"/>
    <origin xyz="-0.15 0.175 -0.1" rpy="1.5708 0 0"/>
    <axis xyz="0 0 1"/>
  </joint>

  <!-- Improved differential drive with better parameters -->
  <gazebo>
    <plugin name="diff_drive" filename="libgazebo_ros_diff_drive.so">
      <ros>
        <namespace>/</namespace>
      </ros>
      <left_joint>left_front_joint</left_joint>
      <right_joint>right_front_joint</right_joint>
      <wheel_separation>0.35</wheel_separation>
      <wheel_diameter>0.2</wheel_diameter>
      <max_wheel_torque>300</max_wheel_torque>
      <max_wheel_acceleration>100.0</max_wheel_acceleration>
      <command_topic>cmd_vel</command_topic>
      <odometry_topic>odom</odometry_topic>
      <odometry_frame>odom</odometry_frame>
      <robot_base_frame>base_link</robot_base_frame>
      <publish_odom>true</publish_odom>
      <publish_odom_tf>true</publish_odom_tf>
      <publish_wheel_tf>false</publish_wheel_tf>
      <update_rate>100</update_rate>
      <!-- Better control parameters -->
      <wheel_acceleration>2</wheel_acceleration>
      <wheel_deceleration>4</wheel_deceleration>
      <torque>20</torque>
    </plugin>
  </gazebo>

  <!-- Gazebo properties for the chassis -->
  <gazebo reference="chassis">
    <material>Gazebo/Blue</material>
  </gazebo>

  <!-- Gazebo properties for the wheels -->
  <gazebo reference="right_front_wheel">
    <material>Gazebo/Black</material>
    <mu1>1.0</mu1>
    <mu2>1.0</mu2>
    <kp>1000000.0</kp>
    <kd>100.0</kd>
  </gazebo>
  <gazebo reference="left_front_wheel">
    <material>Gazebo/Black</material>
    <mu1>1.0</mu1>
    <mu2>1.0</mu2>
    <kp>1000000.0</kp>
    <kd>100.0</kd>
  </gazebo>
  <gazebo reference="right_rear_wheel">
    <material>Gazebo/Black</material>
    <mu1>0.1</mu1>
    <mu2>0.1</mu2>
    <kp>1000000.0</kp>
    <kd>100.0</kd>
    <minDepth>0.001</minDepth>
    <maxVel>0.1</maxVel>
  </gazebo>
  <gazebo reference="left_rear_wheel">
    <material>Gazebo/Black</material>
    <mu1>0.1</mu1>
    <mu2>0.1</mu2>
    <kp>1000000.0</kp>
    <kd>100.0</kd>
    <minDepth>0.001</minDepth>
    <maxVel>0.1</maxVel>
  </gazebo>
</robot>